Workbook

Sheet Juan's Resort
A1: DAE-1B (Manual)
A3: Region: Region IV-A
A4: Juan's Resort
A5: JUNE, 2026
A7: REPORT ON THE REGIONAL DISTRIBUTION OF TRAVELERS
A9: Type of Accommodation
A10: Hotel
A11: Resort | B11: ✔
A12: Pension Inn/ Lodge
A13: Youth Hostel/ Dormitory
A14: Apartel/ Rented Homes/ Apartment
A15: Others, please specify: _________________________
A17: DOT Accreditation Classification: _____________________________
A19: AE ID Code (LGU Assigned): _________________________________________
A20: AE ID Code (LGU Assigned): ____________________________________________
A22: City/Municipality: San Pablo City
A23: Province: Laguna
A25: COUNTRY OF RESIDENCE | B25: 1 | C25: 2 | D25: 3 | E25: 4 | F25: 5 | G25: 6 | H25: 7 | I25: 8 | J25: 9 | K25: 10 | L25: 11 | M25: 12 | N25: 13 | O25: 14 | P25: 15 | Q25: 16 | R25: 17 | S25: 18 | T25: 19 | U25: 20 | V25: 21 | W25: 22 | X25: 23 | Y25: 24 | Z25: 25 | AA25: 26 | AB25: 27 | AC25: 28 | AD25: 29 | AE25: 30 | AF25: 31 | AG25: TOTAL
A27: PHILIPPINE RESIDENTS
A28: FILIPINO NATIONALITY | M28: 2 | N28: 1 | AG28: =SUM(B28:AF28)
A29: FOREIGN NATIONALITY | AG29: =SUM(B29:AF29)
A30: TOTAL PHILIPPINE RESIDENTS | B30: =SUM(B28:B29) | C30: =SUM(C28:C29) | D30: =SUM(D28:D29) | E30: =SUM(E28:E29) | F30: =SUM(F28:F29) | G30: =SUM(G28:G29) | H30: =SUM(H28:H29) | I30: =SUM(I28:I29) | ... AF30: =SUM(AF28:AF29) | AG30: =SUM(B30:AF30)
A32: NON-PHILIPPINE RESIDENTS
A34: ASIA
A35: ASEAN
A36: BRUNEI | AG36: =SUM(B36:AF36)
A37: CAMBODIA | AG37: =SUM(B37:AF37)
A38: INDONESIA | AG38: =SUM(B38:AF38)
A39: LAOS | AG39: =SUM(B39:AF39)
A40: MALAYSIA | AG40: =SUM(B40:AF40)
A41: MYANMAR | AG41: =SUM(B41:AF41)
A42: SINGAPORE | AG42: =SUM(B42:AF42)
A43: THAILAND | AG43: =SUM(B43:AF43)
A44: VIETNAM | AG44: =SUM(B44:AF44)
A45: SUB-TOTAL | B45: =SUM(B36:B44) | C45: =SUM(C36:C44) | D45: =SUM(D36:D44) | E45: =SUM(E36:E44) | F45: =SUM(F36:F44) | G45: =SUM(G36:G44) | H45: =SUM(H36:H44) | I45: =SUM(I36:I44) | ... AF45: =SUM(AF36:AF44) | AG45: =SUM(B45:AF45)
A47: EAST ASIA
A48: CHINA | AG48: =SUM(B48:AF48)
A49: HONGKONG | AG49: =SUM(B49:AF49)
A50: JAPAN | AG50: =SUM(B50:AF50)
A51: KOREA | AG51: =SUM(B51:AF51)
...

Sheet AE DAE-1B by Country (Sum)
A1: DAE-1B(Manual-Summary)
A3: Region: __4-A
A4: All Accommodation Establishments — Combined
A5: JUNE, 2026
A7: REPORT ON THE REGIONAL DISTRIBUTION OF TRAVELERS
A9: Type of Accommodation
A10: Hotel
A11: Resort
A12: Pension Inn/ Lodge
A13: Youth Hostel/ Dormitory
A14: Apartel/ Rented Homes/ Apartment
A15: Others, please specify: _________________________
A17: ='Name of Establishment'!A17 -> DOT Accreditation Classification: _____________________________
A19: ='Name of Establishment'!A19 -> AE ID Code (LGU Assigned): _________________________________________
A20: ='Name of Establishment'!A20 -> AE ID Code (LGU Assigned): ____________________________________________
A22: ='Name of Establishment'!A22 -> City/Municipality: ___________________
A23: ='Name of Establishment'!A23 -> Province: _____________________
A25: COUNTRY OF RESIDENCE | B25: TOTAL
A27: PHILIPPINE RESIDENTS
A28: FILIPINO NATIONALITY | B28: 3
A29: FOREIGN NATIONALITY | B29: 0
A30: TOTAL PHILIPPINE RESIDENTS | B30: ='Name of Establishment'!AG30
A32: NON-PHILIPPINE RESIDENTS
A34: ASIA
A35: ASEAN
A36: BRUNEI | B36: 0
A37: CAMBODIA | B37: 0
A38: INDONESIA | B38: 0
A39: LAOS | B39: 0
A40: MALAYSIA | B40: 0
A41: MYANMAR | B41: 0
A42: SINGAPORE | B42: 0
A43: THAILAND | B43: 0
A44: VIETNAM | B44: 0
A45: SUB-TOTAL | B45: ='Name of Establishment'!AG45
A47: EAST ASIA
A48: CHINA | B48: 0
A49: HONGKONG | B49: 0
A50: JAPAN | B50: 0
A51: KOREA | B51: 0
...

Sheet AE DAE-1B (Monthly) Summary
A1: DAE-1B(Manual-Summary)
A3: Region: __4-A
A4: All Accommodation Establishments — Combined
A5: 2026
A7: REPORT ON THE REGIONAL DISTRIBUTION OF TRAVELERS
A9: Type of Accommodation
A10: Hotel
A11: Resort
A12: Pension Inn/ Lodge
A13: Youth Hostel/ Dormitory
A14: Apartel/ Rented Homes/ Apartment
A15: Others, please specify: _________________________
A17: ='Name of Establishment'!A17 -> DOT Accreditation Classification: _____________________________
A19: ='Name of Establishment'!A19 -> AE ID Code (LGU Assigned): _________________________________________
A20: ='Name of Establishment'!A20 -> AE ID Code (LGU Assigned): ____________________________________________
A22: ='Name of Establishment'!A22 -> City/Municipality: ___________________
A23: ='Name of Establishment'!A23 -> Province: _____________________
A25: COUNTRY OF RESIDENCE | B25: JANUARY | C25: FEBRUARY | D25: MARCH | E25: APRIL | F25: MAY | G25: JUNE | H25: JULY | I25: AUGUST | J25: SEPTEMBER | K25: OCTOBER | L25: NOVEMBER | M25: DECEMBER | N25: TOTAL
A27: PHILIPPINE RESIDENTS
A28: FILIPINO NATIONALITY | B28: 0 | C28: 0 | D28: 0 | E28: 0 | F28: 0 | G28: 3 | H28: 0 | I28: 0 | J28: 0 | K28: 0 | L28: 0 | M28: 0 | N28: =SUM(B28:M28)
A29: FOREIGN NATIONALITY | B29: 0 | C29: 0 | D29: 0 | E29: 0 | F29: 0 | G29: 0 | H29: 0 | I29: 0 | J29: 0 | K29: 0 | L29: 0 | M29: 0 | N29: =SUM(B29:M29)
A30: TOTAL PHILIPPINE RESIDENTS | B30: =SUM(B28:B29) | C30: =SUM(C28:C29) | D30: =SUM(D28:D29) | E30: =SUM(E28:E29) | F30: =SUM(F28:F29) | G30: =SUM(G28:G29) | H30: =SUM(H28:H29) | I30: =SUM(I28:I29) | ... M30: =SUM(M28:M29) | N30: =SUM(B30:M30)
A32: NON-PHILIPPINE RESIDENTS
A34: ASIA
A35: ASEAN
A36: BRUNEI | B36: 0 | C36: 0 | D36: 0 | E36: 0 | F36: 0 | G36: 0 | H36: 0 | I36: 0 | J36: 0 | K36: 0 | L36: 0 | M36: 0 | N36: =SUM(B36:M36)
A37: CAMBODIA | B37: 0 | C37: 0 | D37: 0 | E37: 0 | F37: 0 | G37: 0 | H37: 0 | I37: 0 | J37: 0 | K37: 0 | L37: 0 | M37: 0 | N37: =SUM(B37:M37)
A38: INDONESIA | B38: 0 | C38: 0 | D38: 0 | E38: 0 | F38: 0 | G38: 0 | H38: 0 | I38: 0 | J38: 0 | K38: 0 | L38: 0 | M38: 0 | N38: =SUM(B38:M38)
A39: LAOS | B39: 0 | C39: 0 | D39: 0 | E39: 0 | F39: 0 | G39: 0 | H39: 0 | I39: 0 | J39: 0 | K39: 0 | L39: 0 | M39: 0 | N39: =SUM(B39:M39)
A40: MALAYSIA | B40: 0 | C40: 0 | D40: 0 | E40: 0 | F40: 0 | G40: 0 | H40: 0 | I40: 0 | J40: 0 | K40: 0 | L40: 0 | M40: 0 | N40: =SUM(B40:M40)
A41: MYANMAR | B41: 0 | C41: 0 | D41: 0 | E41: 0 | F41: 0 | G41: 0 | H41: 0 | I41: 0 | J41: 0 | K41: 0 | L41: 0 | M41: 0 | N41: =SUM(B41:M41)
A42: SINGAPORE | B42: 0 | C42: 0 | D42: 0 | E42: 0 | F42: 0 | G42: 0 | H42: 0 | I42: 0 | J42: 0 | K42: 0 | L42: 0 | M42: 0 | N42: =SUM(B42:M42)
A43: THAILAND | B43: 0 | C43: 0 | D43: 0 | E43: 0 | F43: 0 | G43: 0 | H43: 0 | I43: 0 | J43: 0 | K43: 0 | L43: 0 | M43: 0 | N43: =SUM(B43:M43)
A44: VIETNAM | B44: 0 | C44: 0 | D44: 0 | E44: 0 | F44: 0 | G44: 0 | H44: 0 | I44: 0 | J44: 0 | K44: 0 | L44: 0 | M44: 0 | N44: =SUM(B44:M44)
A45: SUB-TOTAL | B45: =SUM(B36:B44) | C45: =SUM(C36:C44) | D45: =SUM(D36:D44) | E45: =SUM(E36:E44) | F45: =SUM(F36:F44) | G45: =SUM(G36:G44) | H45: =SUM(H36:H44) | I45: =SUM(I36:I44) | ... M45: =SUM(M36:M44) | N45: =SUM(B45:M45)
A47: EAST ASIA
A48: CHINA | B48: 0 | C48: 0 | D48: 0 | E48: 0 | F48: 0 | G48: 0 | H48: 0 | I48: 0 | J48: 0 | K48: 0 | L48: 0 | M48: 0 | N48: =SUM(B48:M48)
A49: HONGKONG | B49: 0 | C49: 0 | D49: 0 | E49: 0 | F49: 0 | G49: 0 | H49: 0 | I49: 0 | J49: 0 | K49: 0 | L49: 0 | M49: 0 | N49: =SUM(B49:M49)
A50: JAPAN | B50: 0 | C50: 0 | D50: 0 | E50: 0 | F50: 0 | G50: 0 | H50: 0 | I50: 0 | J50: 0 | K50: 0 | L50: 0 | M50: 0 | N50: =SUM(B50:M50)
A51: KOREA | B51: 0 | C51: 0 | D51: 0 | E51: 0 | F51: 0 | G51: 0 | H51: 0 | I51: 0 | J51: 0 | K51: 0 | L51: 0 | M51: 0 | N51: =SUM(B51:M51)
...
