Workbook

Sheet Name of Establishment
A1: Sample Resort & Spa
A3: Region: __4-A
A4: January 2025
A5: (Month, Year)
A7: REPORT ON THE REGIONAL DISTRIBUTION OF TRAVELERS
A9: Type of Accommodation
A10: Hotel
A11: Resort
A12: Pension Inn/ Lodge
A13: Youth Hostel/ Dormitory
A14: Apartel/ Rented Homes/ Apartment
A15: Others, please specify: _________________________
... A23: Province: Quezon
A25: COUNTRY OF RESIDENCE | B25: 1 | C25: 2 | D25: 3 | E25: 4 | F25: 5 | G25: 6 | H25: 7 | I25: 8 | J25: 9 | K25: 10 | L25: 11 | M25: 12 | N25: 13 | O25: 14 | P25: 15 | Q25: 16 | R25: 17 | S25: 18 | T25: 19 | U25: 20 | V25: 21 | W25: 22 | X25: 23 | Y25: 24 | Z25: 25 | AA25: 26 | AB25: 27 | AC25: 28 | AD25: 29 | AE25: 30 | AF25: 31 | AG25: TOTAL
A27: PHILIPPINE RESIDENTS
A28: FILIPINO NATIONALITY | B28: 20 | C28: 18 | D28: 22 | E28: 25 | F28: 30 | G28: 28 | H28: 35 | I28: 32 | J28: 27 | K28: 24 | L28: 22 | M28: 20 | N28: 18 | O28: 21 | P28: 23 | Q28: 25 | R28: 28 | S28: 30 | T28: 32 | U28: 29 | V28: 26 | W28: 24 | X28: 22 | Y28: 20 | Z28: 18 | AA28: 21 | AB28: 25 | AC28: 28 | AD28: 30 | AE28: 27 | AF28: 24 | AG28: =SUM(B28:AF28) -> 0
A29: FOREIGN NATIONALITY | B29: 2 | C29: 2 | D29: 3 | E29: 5 | F29: 0 | G29: 0 | H29: 5 | I29: 3 | J29: 5 | K29: 3 | L29: 0 | M29: 3 | N29: 2 | O29: 3 | P29: 3 | Q29: 2 | R29: 4 | S29: 0 | T29: 0 | U29: 2 | V29: 5 | W29: 4 | X29: 5 | Y29: 5 | Z29: 3 | AA29: 4 | AB29: 3 | AC29: 4 | AD29: 5 | AE29: 1 | AF29: 3 | AG29: =SUM(B29:AF29) -> 0
A30: TOTAL PHILIPPINE RESIDENTS | B30: =SUM(B28:B29) -> 0 | C30: =SUM(C28:C29) -> 0 | D30: =SUM(D28:D29) -> 0 | E30: =SUM(E28:E29) -> 0 | F30: =SUM(F28:F29) -> 0 | G30: =SUM(G28:G29) -> 0 | H30: =SUM(H28:H29) -> 0 | I30: =SUM(I28:I29) -> 0 | ... AF30: =SUM(AF28:AF29) -> 0 | AG30: =SUM(B30:AF30) -> 0
A32: NON-PHILIPPINE RESIDENTS
A34: ASIA
A35: ASEAN
A36: BRUNEI | B36: 3 | C36: 4 | D36: 3 | E36: 5 | F36: 1 | G36: 1 | H36: 1 | I36: 2 | J36: 0 | K36: 4 | L36: 3 | M36: 0 | N36: 2 | O36: 3 | P36: 5 | Q36: 2 | R36: 3 | S36: 4 | T36: 5 | U36: 0 | V36: 0 | W36: 5 | X36: 5 | Y36: 1 | Z36: 5 | AA36: 3 | AB36: 0 | AC36: 1 | AD36: 3 | AE36: 3 | AF36: 0 | AG36: =SUM(B36:AF36) -> 0
A37: CAMBODIA | B37: 1 | C37: 2 | D37: 0 | E37: 2 | F37: 2 | G37: 4 | H37: 3 | I37: 0 | J37: 0 | K37: 2 | L37: 0 | M37: 0 | N37: 5 | O37: 4 | P37: 0 | Q37: 4 | R37: 1 | S37: 3 | T37: 5 | U37: 1 | V37: 5 | W37: 1 | X37: 5 | Y37: 2 | Z37: 4 | AA37: 0 | AB37: 4 | AC37: 3 | AD37: 3 | AE37: 3 | AF37: 4 | AG37: =SUM(B37:AF37) -> 0
A38: INDONESIA | B38: 1 | C38: 0 | D38: 3 | E38: 3 | F38: 4 | G38: 5 | H38: 4 | I38: 0 | J38: 4 | K38: 4 | L38: 2 | M38: 3 | N38: 1 | O38: 5 | P38: 2 | Q38: 4 | R38: 4 | S38: 5 | T38: 3 | U38: 5 | V38: 0 | W38: 0 | X38: 3 | Y38: 2 | Z38: 4 | AA38: 0 | AB38: 0 | AC38: 4 | AD38: 0 | AE38: 4 | AF38: 1 | AG38: =SUM(B38:AF38) -> 0
A39: LAOS | B39: 0 | C39: 4 | D39: 3 | E39: 4 | F39: 0 | G39: 5 | H39: 2 | I39: 0 | J39: 4 | K39: 1 | L39: 5 | M39: 4 | N39: 1 | O39: 4 | P39: 3 | Q39: 4 | R39: 5 | S39: 4 | T39: 1 | U39: 1 | V39: 3 | W39: 1 | X39: 3 | Y39: 5 | Z39: 2 | AA39: 0 | AB39: 0 | AC39: 0 | AD39: 3 | AE39: 2 | AF39: 4 | AG39: =SUM(B39:AF39) -> 0
A40: MALAYSIA | B40: 3 | C40: 2 | D40: 5 | E40: 0 | F40: 4 | G40: 0 | H40: 5 | I40: 0 | J40: 3 | K40: 3 | L40: 1 | M40: 0 | N40: 2 | O40: 5 | P40: 2 | Q40: 3 | R40: 3 | S40: 2 | T40: 3 | U40: 1 | V40: 1 | W40: 5 | X40: 2 | Y40: 2 | Z40: 3 | AA40: 4 | AB40: 4 | AC40: 2 | AD40: 4 | AE40: 5 | AF40: 1 | AG40: =SUM(B40:AF40) -> 0
A41: MYANMAR | B41: 3 | C41: 3 | D41: 5 | E41: 5 | F41: 2 | G41: 0 | H41: 4 | I41: 2 | J41: 1 | K41: 0 | L41: 0 | M41: 5 | N41: 3 | O41: 4 | P41: 5 | Q41: 2 | R41: 5 | S41: 2 | T41: 4 | U41: 1 | V41: 4 | W41: 3 | X41: 4 | Y41: 3 | Z41: 1 | AA41: 1 | AB41: 1 | AC41: 1 | AD41: 5 | AE41: 4 | AF41: 4 | AG41: =SUM(B41:AF41) -> 0
A42: SINGAPORE | B42: 5 | C42: 1 | D42: 5 | E42: 1 | F42: 5 | G42: 1 | H42: 2 | I42: 2 | J42: 4 | K42: 1 | L42: 1 | M42: 0 | N42: 2 | O42: 0 | P42: 3 | Q42: 2 | R42: 0 | S42: 1 | T42: 5 | U42: 3 | V42: 0 | W42: 0 | X42: 4 | Y42: 1 | Z42: 0 | AA42: 2 | AB42: 1 | AC42: 2 | AD42: 2 | AE42: 2 | AF42: 0 | AG42: =SUM(B42:AF42) -> 0
A43: THAILAND | B43: 5 | C43: 0 | D43: 1 | E43: 1 | F43: 3 | G43: 1 | H43: 5 | I43: 3 | J43: 5 | K43: 5 | L43: 4 | M43: 5 | N43: 3 | O43: 4 | P43: 2 | Q43: 0 | R43: 1 | S43: 1 | T43: 0 | U43: 4 | V43: 2 | W43: 0 | X43: 1 | Y43: 1 | Z43: 4 | AA43: 2 | AB43: 3 | AC43: 5 | AD43: 2 | AE43: 3 | AF43: 2 | AG43: =SUM(B43:AF43) -> 0
A44: VIETNAM | B44: 2 | C44: 4 | D44: 1 | E44: 0 | F44: 3 | G44: 5 | H44: 4 | I44: 2 | J44: 5 | K44: 0 | L44: 2 | M44: 5 | N44: 1 | O44: 3 | P44: 1 | Q44: 3 | R44: 3 | S44: 4 | T44: 4 | U44: 4 | V44: 4 | W44: 2 | X44: 3 | Y44: 1 | Z44: 3 | AA44: 0 | AB44: 3 | AC44: 1 | AD44: 1 | AE44: 4 | AF44: 5 | AG44: =SUM(B44:AF44) -> 0
A45: SUB-TOTAL | B45: =SUM(B36:B44) -> 0 | C45: =SUM(C36:C44) -> 0 | D45: =SUM(D36:D44) -> 0 | E45: =SUM(E36:E44) -> 0 | F45: =SUM(F36:F44) -> 0 | G45: =SUM(G36:G44) -> 0 | H45: =SUM(H36:H44) -> 0 | I45: =SUM(I36:I44) -> 0 | ... AF45: =SUM(AF36:AF44) -> 0 | AG45: =SUM(B45:AF45) -> 0
A47: EAST ASIA
A48: CHINA | B48: 4 | C48: 4 | D48: 0 | E48: 5 | F48: 2 | G48: 3 | H48: 4 | I48: 2 | J48: 2 | K48: 1 | L48: 3 | M48: 0 | N48: 2 | O48: 2 | P48: 1 | Q48: 4 | R48: 0 | S48: 3 | T48: 2 | U48: 3 | V48: 3 | W48: 5 | X48: 2 | Y48: 3 | Z48: 0 | AA48: 4 | AB48: 5 | AC48: 0 | AD48: 2 | AE48: 5 | AF48: 3 | AG48: =SUM(B48:AF48) -> 0
A49: HONGKONG | B49: 1 | C49: 3 | D49: 0 | E49: 5 | F49: 1 | G49: 4 | H49: 0 | I49: 2 | J49: 2 | K49: 3 | L49: 3 | M49: 5 | N49: 2 | O49: 2 | P49: 2 | Q49: 4 | R49: 0 | S49: 3 | T49: 3 | U49: 0 | V49: 5 | W49: 4 | X49: 3 | Y49: 4 | Z49: 5 | AA49: 4 | AB49: 4 | AC49: 3 | AD49: 5 | AE49: 3 | AF49: 4 | AG49: =SUM(B49:AF49) -> 0
A50: JAPAN | B50: 4 | C50: 3 | D50: 3 | E50: 4 | F50: 1 | G50: 3 | H50: 2 | I50: 5 | J50: 5 | K50: 3 | L50: 4 | M50: 4 | N50: 3 | O50: 1 | P50: 5 | Q50: 2 | R50: 3 | S50: 1 | T50: 2 | U50: 1 | V50: 4 | W50: 3 | X50: 3 | Y50: 3 | Z50: 1 | AA50: 1 | AB50: 5 | AC50: 5 | AD50: 2 | AE50: 0 | AF50: 4 | AG50: =SUM(B50:AF50) -> 0
A51: KOREA | B51: 3 | C51: 0 | D51: 4 | E51: 4 | F51: 3 | G51: 3 | H51: 5 | I51: 1 | J51: 0 | K51: 3 | L51: 5 | M51: 5 | N51: 2 | O51: 3 | P51: 5 | Q51: 1 | R51: 5 | S51: 3 | T51: 0 | U51: 1 | V51: 3 | W51: 5 | X51: 0 | Y51: 2 | Z51: 4 | AA51: 2 | AB51: 3 | AC51: 2 | AD51: 1 | AE51: 4 | AF51: 5 | AG51: =SUM(B51:AF51) -> 0
A52: TAIWAN | B52: 0 | C52: 4 | D52: 1 | E52: 2 | F52: 0 | G52: 5 | H52: 2 | I52: 4 | J52: 1 | K52: 5 | L52: 0 | M52: 1 | N52: 4 | O52: 2 | P52: 5 | Q52: 3 | R52: 3 | S52: 5 | T52: 1 | U52: 2 | V52: 2 | W52: 5 | X52: 0 | Y52: 5 | Z52: 1 | AA52: 3 | AB52: 4 | AC52: 2 | AD52: 5 | AE52: 3 | AF52: 1 | AG52: =SUM(B52:AF52) -> 0
A53: SUB-TOTAL | B53: =SUM(B48:B52) -> 0 | C53: =SUM(C48:C52) -> 0 | D53: =SUM(D48:D52) -> 0 | E53: =SUM(E48:E52) -> 0 | F53: =SUM(F48:F52) -> 0 | G53: =SUM(G48:G52) -> 0 | H53: =SUM(H48:H52) -> 0 | I53: =SUM(I48:I52) -> 0 | ... AF53: =SUM(AF48:AF52) -> 0 | AG53: =SUM(B53:AF53) -> 0
A55: SOUTH ASIA
A56: BANGLADESH | AG56: =SUM(B56:AF56) -> 0
...

Sheet AE DAE-1B by Country (Sum) 
A1: DAE-1B(Manual-Summary)
A3: ='Name of Establishment'!A3:AG3 -> Region: __4-A
A4: ='Name of Establishment'!A4:AG4 -> ____________________________________
A5: (Month, Year)
A7: REPORT ON THE REGIONAL DISTRIBUTION OF TRAVELERS
A9: Type of Accommodation
A10: Hotel
A11: Resort
A12: Pension Inn/ Lodge
A13: Youth Hostel/ Dormitory
A14: Apartel/ Rented Homes/ Apartment
A15: Others, please specify: _________________________
A17: ='Name of Establishment'!A17 -> DOT Accreditation Classification: _____________________________
A19: ='Name of Establishment'!A19 -> AE ID Code (LGU Assigned): _________________________________________
A20: ='Name of Establishment'!A20 -> AE ID Code (LGU Assigned): ____________________________________________
A22: ='Name of Establishment'!A22 -> City/Municipality: ___________________
A23: ='Name of Establishment'!A23 -> Province: _____________________
A25: COUNTRY OF RESIDENCE | B25: TOTAL
A27: PHILIPPINE RESIDENTS
A28: FILIPINO NATIONALITY | B28: ='Name of Establishment'!AG28 -> 0
A29: FOREIGN NATIONALITY | B29: ='Name of Establishment'!AG29 -> 0
A30: TOTAL PHILIPPINE RESIDENTS | B30: ='Name of Establishment'!AG30 -> 0
A32: NON-PHILIPPINE RESIDENTS
A34: ASIA
A35: ASEAN
A36: BRUNEI | B36: ='Name of Establishment'!AG36 -> 0
A37: CAMBODIA | B37: ='Name of Establishment'!AG37 -> 0
A38: INDONESIA | B38: ='Name of Establishment'!AG38 -> 0
A39: LAOS | B39: ='Name of Establishment'!AG39 -> 0
A40: MALAYSIA | B40: ='Name of Establishment'!AG40 -> 0
A41: MYANMAR | B41: ='Name of Establishment'!AG41 -> 0
A42: SINGAPORE | B42: ='Name of Establishment'!AG42 -> 0
A43: THAILAND | B43: ='Name of Establishment'!AG43 -> 0
A44: VIETNAM | B44: ='Name of Establishment'!AG44 -> 0
A45: SUB-TOTAL | B45: ='Name of Establishment'!AG45 -> 0
A47: EAST ASIA
A48: CHINA | B48: ='Name of Establishment'!AG48 -> 0
A49: HONGKONG | B49: ='Name of Establishment'!AG49 -> 0
A50: JAPAN | B50: ='Name of Establishment'!AG50 -> 0
A51: KOREA | B51: ='Name of Establishment'!AG51 -> 0
...

Sheet AE DAE-1B (Monthly)
A1: DAE-1B(Manual-Summary)
A3: ='Name of Establishment'!A3:AG3 -> Region: __4-A
A4: ='Name of Establishment'!A4:AG4 -> ____________________________________
A5: (Month, Year)
A7: REPORT ON THE REGIONAL DISTRIBUTION OF TRAVELERS
A9: Type of Accommodation
A10: Hotel
A11: Resort
A12: Pension Inn/ Lodge
A13: Youth Hostel/ Dormitory
A14: Apartel/ Rented Homes/ Apartment
A15: Others, please specify: _________________________
A17: ='Name of Establishment'!A17 -> DOT Accreditation Classification: _____________________________
A19: ='Name of Establishment'!A19 -> AE ID Code (LGU Assigned): _________________________________________
A20: ='Name of Establishment'!A20 -> AE ID Code (LGU Assigned): ____________________________________________
A22: ='Name of Establishment'!A22 -> City/Municipality: ___________________
A23: ='Name of Establishment'!A23 -> Province: _____________________
A25: COUNTRY OF RESIDENCE | B25: JANUARY | C25: FEBRUARY | D25: MARCH | E25: APRIL | F25: MAY | G25: JUNE | H25: JULY | I25: AUGUST | J25: SEPTEMBER | K25: OCTOBER | L25: NOVEMBER | M25: DECEMBER | N25: TOTAL
A27: PHILIPPINE RESIDENTS
A28: FILIPINO NATIONALITY | B28: 774 | N28: =SUM(B28:M28) -> 0
A29: FOREIGN NATIONALITY | B29: 89 | N29: =SUM(B29:M29) -> 0
A30: TOTAL PHILIPPINE RESIDENTS | B30: =SUM(B28:B29) -> 0 | C30: =SUM(C28:C29) -> 0 | D30: =SUM(D28:D29) -> 0 | E30: =SUM(E28:E29) -> 0 | F30: =SUM(F28:F29) -> 0 | G30: =SUM(G28:G29) -> 0 | H30: =SUM(H28:H29) -> 0 | I30: =SUM(I28:I29) -> 0 | ... M30: =SUM(M28:M29) -> 0 | N30: =SUM(B30:M30) -> 0
A32: NON-PHILIPPINE RESIDENTS
A34: ASIA
A35: ASEAN
A36: BRUNEI | B36: 77 | N36: =SUM(B36:M36) -> 0
A37: CAMBODIA | B37: 73 | N37: =SUM(B37:M37) -> 0
A38: INDONESIA | B38: 80 | N38: =SUM(B38:M38) -> 0
A39: LAOS | B39: 78 | N39: =SUM(B39:M39) -> 0
A40: MALAYSIA | B40: 80 | N40: =SUM(B40:M40) -> 0
A41: MYANMAR | B41: 87 | N41: =SUM(B41:M41) -> 0
A42: SINGAPORE | B42: 58 | N42: =SUM(B42:M42) -> 0
A43: THAILAND | B43: 78 | N43: =SUM(B43:M43) -> 0
A44: VIETNAM | B44: 83 | N44: =SUM(B44:M44) -> 0
A45: SUB-TOTAL | B45: =SUM(B36:B44) -> 0 | C45: =SUM(C36:C44) -> 0 | D45: =SUM(D36:D44) -> 0 | E45: =SUM(E36:E44) -> 0 | F45: =SUM(F36:F44) -> 0 | G45: =SUM(G36:G44) -> 0 | H45: =SUM(H36:H44) -> 0 | I45: =SUM(I36:I44) -> 0 | ... M45: =SUM(M36:M44) -> 0 | N45: =SUM(B45:M45) -> 0
A47: EAST ASIA
A48: CHINA | B48: 79 | N48: =SUM(B48:M48) -> 0
A49: HONGKONG | B49: 89 | N49: =SUM(B49:M49) -> 0
A50: JAPAN | B50: 90 | N50: =SUM(B50:M50) -> 0
A51: KOREA | B51: 87 | N51: =SUM(B51:M51) -> 0
...
